<mujoco model="a1">
    <compiler angle="radian" meshdir="meshes" autolimits="true" />

    <size njmax="500" nconmax="100" />
    <option gravity='0 0 -9.806' iterations='50' solver='Newton' timestep='0.002' cone="elliptic" impratio="100" >
        <flag sensornoise="enable" />
    </option>

    <default>
        <geom contype="1" conaffinity="1" friction="0.6" rgba="0.5 0.6 0.7 1" margin="0.001" group="0"/>

        <light castshadow="false" diffuse="1 1 1"/>
        <motor ctrlrange="-33.5 33.5" ctrllimited="true"/>
        <camera fovy="60"/>
        <joint damping="0.01" armature="0.01" frictionloss="0.2" />
    
    </default>

    <asset>
        <mesh name="trunk" file="trunk.stl" />
        <mesh name="hip" file="hip.stl" />
        <mesh name="thigh_mirror" file="thigh_mirror.stl" />
        <mesh name="calf" file="calf.stl" />
        <mesh name="thigh" file="thigh.stl" />
    </asset>

    <visual>
        <rgba com="0.502 1.0 0 0.5" contactforce="0.98 0.4 0.4 0.7" contactpoint="1.0 1.0 0.6 0.4"/>
        <scale com="0.2" forcewidth="0.035" contactwidth="0.10" contactheight="0.04"/>
    </visual>

    <worldbody>
        <body name="trunk" pos="0 0 0.3">
            <inertial pos="0.0127283 0.00218554 0.000514891" quat="0.00186575 0.711506 0.000389649 0.702677" mass="4.713" diaginertia="0.0648213 0.0565803 0.0169323" />
            <joint type="free" />
            <!-- <joint type="free" stiffness="10000" damping="1000000" frictionloss="0" armature="0" /> -->
            <geom type="mesh" contype="0" conaffinity="0" group="1" rgba="0.913725 0.913725 0.847059 1" mesh="trunk" />
            <geom size="0.1335 0.066 0.057" type="box" rgba="0.913725 0.913725 0.847059 0" />
            <geom size="0.0005 0.0005 0.0005" type="box" contype="0" conaffinity="0" group="1" rgba="0.8 0 0 0" />
            <geom size="0.0005 0.0005 0.0005" type="box" rgba="0.8 0 0 0" />
            <site name="imu" pos="0 0 0"/>

            <body name="FR_hip" pos="0.183 -0.047 0">
                <inertial pos="-0.003311 -0.000635 3.1e-05" quat="0.507528 0.506268 0.491507 0.494499" mass="0.696" diaginertia="0.000807752 0.00055293 0.000468983" />
                <joint name="FR_hip_joint" pos="0 0 0" axis="1 0 0" limited="true" range="-0.802851 0.802851" />
                <geom quat="0 1 0 0" type="mesh" contype="0" conaffinity="0" group="1" rgba="0.913725 0.913725 0.847059 1" mesh="hip" />
                <geom size="0.04 0.04" pos="0 -0.055 0" quat="0.707107 0.707107 0 0" type="cylinder" rgba="0.913725 0.913725 0.847059 0" />
                <body name="FR_thigh" pos="0 -0.08505 0">
                    <inertial pos="-0.003237 0.022327 -0.027326" quat="0.999125 -0.00256393 -0.0409531 -0.00806091" mass="1.013" diaginertia="0.00555739 0.00513936 0.00133944" />
                    <joint name="FR_thigh_joint" pos="0 0 0" axis="0 1 0" limited="true" range="-1.0472 4.18879" />
                    <geom type="mesh" contype="0" conaffinity="0" group="1" rgba="0.913725 0.913725 0.847059 1" mesh="thigh_mirror" />
                    <geom size="0.1 0.01225 0.017" pos="0 0 -0.1" quat="0.707107 0 0.707107 0" type="box" rgba="0.913725 0.913725 0.847059 0" />
                    <body name="FR_calf" pos="0 0 -0.2">
                        <inertial pos="0.00472659 0 -0.131975" quat="0.706886 0.017653 0.017653 0.706886" mass="0.226" diaginertia="0.00340344 0.00339393 3.54834e-05" />
                        <joint name="FR_calf_joint" pos="0 0 0" axis="0 1 0" limited="true" range="-2.69653 -0.916298" />
                        <geom type="mesh" contype="0" conaffinity="0" group="1" rgba="0 0 0 1" mesh="calf" />
                        <geom size="0.1 0.008 0.008" pos="0 0 -0.1" quat="0.707107 0 0.707107 0" type="box" rgba="0 0 0 0" />
                        <geom size="0.01" pos="0 0 -0.2" contype="0" conaffinity="0" group="1" rgba="0 0 0 1" />
                        <!-- <geom size="0.02" pos="0 0 -0.2" rgba="0 0 0 1" /> -->
                        <geom type="sphere" size="0.02" pos="0 0 -0.2" priority="1" solimp="0.015 1 0.031" condim="6" friction="0.6" />
                        <site name="FR_foot" pos="0 0 -0.2" type="sphere" size=".015" />
                    </body>
                </body>
            </body>
            <body name="FL_hip" pos="0.183 0.047 0">
                <inertial pos="-0.003311 0.000635 3.1e-05" quat="0.494499 0.491507 0.506268 0.507528" mass="0.696" diaginertia="0.000807752 0.00055293 0.000468983" />
                <joint name="FL_hip_joint" pos="0 0 0" axis="1 0 0" limited="true" range="-0.802851 0.802851" />
                <geom type="mesh" contype="0" conaffinity="0" group="1" rgba="0.913725 0.913725 0.847059 1" mesh="hip" />
                <geom size="0.04 0.04" pos="0 0.055 0" quat="0.707107 0.707107 0 0" type="cylinder" rgba="0.913725 0.913725 0.847059 0" />
                <body name="FL_thigh" pos="0 0.08505 0">
                    <inertial pos="-0.003237 -0.022327 -0.027326" quat="0.999125 0.00256393 -0.0409531 0.00806091" mass="1.013" diaginertia="0.00555739 0.00513936 0.00133944" />
                    <joint name="FL_thigh_joint" pos="0 0 0" axis="0 1 0" limited="true" range="-1.0472 4.18879" />
                    <geom type="mesh" contype="0" conaffinity="0" group="1" rgba="0.913725 0.913725 0.847059 1" mesh="thigh" />
                    <geom size="0.1 0.01225 0.017" pos="0 0 -0.1" quat="0.707107 0 0.707107 0" type="box" rgba="0.913725 0.913725 0.847059 0" />
                    <body name="FL_calf" pos="0 0 -0.2">
                        <inertial pos="0.00472659 0 -0.131975" quat="0.706886 0.017653 0.017653 0.706886" mass="0.226" diaginertia="0.00340344 0.00339393 3.54834e-05" />
                        <joint name="FL_calf_joint" pos="0 0 0" axis="0 1 0" limited="true" range="-2.69653 -0.916298" />
                        <geom type="mesh" contype="0" conaffinity="0" group="1" rgba="0 0 0 1" mesh="calf" />
                        <geom size="0.1 0.008 0.008" pos="0 0 -0.1" quat="0.707107 0 0.707107 0" type="box" rgba="0 0 0 0" />
                        <geom size="0.01" pos="0 0 -0.2" contype="0" conaffinity="0" group="1" rgba="0 0 0 1" />
                        <!-- <geom size="0.02" pos="0 0 -0.2" rgba="0 0 0 1" /> -->
                        <geom type="sphere" size="0.02" pos="0 0 -0.2" priority="1" solimp="0.015 1 0.031" condim="6" friction="0.6" />
                        <site name="FL_foot" pos="0 0 -0.2" type="sphere" size=".015" />
                    </body>
                </body>
            </body>
            <body name="RR_hip" pos="-0.183 -0.047 0">
                <inertial pos="0.003311 -0.000635 3.1e-05" quat="0.491507 0.494499 0.507528 0.506268" mass="0.696" diaginertia="0.000807752 0.00055293 0.000468983" />
                <joint name="RR_hip_joint" pos="0 0 0" axis="1 0 0" limited="true" range="-0.802851 0.802851" />
                <geom quat="0 0 0 -1" type="mesh" contype="0" conaffinity="0" group="1" rgba="0.913725 0.913725 0.847059 1" mesh="hip" />
                <geom size="0.04 0.04" pos="0 -0.055 0" quat="0.707107 0.707107 0 0" type="cylinder" rgba="0.913725 0.913725 0.847059 0" />
                <body name="RR_thigh" pos="0 -0.08505 0">
                    <inertial pos="-0.003237 0.022327 -0.027326" quat="0.999125 -0.00256393 -0.0409531 -0.00806091" mass="1.013" diaginertia="0.00555739 0.00513936 0.00133944" />
                    <joint name="RR_thigh_joint" pos="0 0 0" axis="0 1 0" limited="true" range="-1.0472 4.18879" />
                    <geom type="mesh" contype="0" conaffinity="0" group="1" rgba="0.913725 0.913725 0.847059 1" mesh="thigh_mirror" />
                    <geom size="0.1 0.01225 0.017" pos="0 0 -0.1" quat="0.707107 0 0.707107 0" type="box" rgba="0.913725 0.913725 0.847059 0" />
                    <body name="RR_calf" pos="0 0 -0.2">
                        <inertial pos="0.00472659 0 -0.131975" quat="0.706886 0.017653 0.017653 0.706886" mass="0.226" diaginertia="0.00340344 0.00339393 3.54834e-05" />
                        <joint name="RR_calf_joint" pos="0 0 0" axis="0 1 0" limited="true" range="-2.69653 -0.916298" />
                        <geom type="mesh" contype="0" conaffinity="0" group="1" rgba="0 0 0 1" mesh="calf" />
                        <geom size="0.1 0.008 0.008" pos="0 0 -0.1" quat="0.707107 0 0.707107 0" type="box" rgba="0 0 0 0" />
                        <geom size="0.01" pos="0 0 -0.2" contype="0" conaffinity="0" group="1" rgba="0 0 0 1" />
                        <!-- <geom size="0.02" pos="0 0 -0.2" rgba="0 0 0 1" /> -->
                        <geom type="sphere" size="0.02" pos="0 0 -0.2" priority="1" solimp="0.015 1 0.031" condim="6" friction="0.6" />
                        <site name="RR_foot" pos="0 0 -0.2" type="sphere" size=".015" />
                    </body>
                </body>
            </body>
            <body name="RL_hip" pos="-0.183 0.047 0">
                <inertial pos="0.003311 0.000635 3.1e-05" quat="0.506268 0.507528 0.494499 0.491507" mass="0.696" diaginertia="0.000807752 0.00055293 0.000468983" />
                <joint name="RL_hip_joint" pos="0 0 0" axis="1 0 0" limited="true" range="-0.802851 0.802851" />
                <geom quat="0 0 1 0" type="mesh" contype="0" conaffinity="0" group="1" rgba="0.913725 0.913725 0.847059 1" mesh="hip" />
                <geom size="0.04 0.04" pos="0 0.055 0" quat="0.707107 0.707107 0 0" type="cylinder" rgba="0.913725 0.913725 0.847059 0" />
                <body name="RL_thigh" pos="0 0.08505 0">
                    <inertial pos="-0.003237 -0.022327 -0.027326" quat="0.999125 0.00256393 -0.0409531 0.00806091" mass="1.013" diaginertia="0.00555739 0.00513936 0.00133944" />
                    <joint name="RL_thigh_joint" pos="0 0 0" axis="0 1 0" limited="true" range="-1.0472 4.18879" />
                    <geom type="mesh" contype="0" conaffinity="0" group="1" rgba="0.913725 0.913725 0.847059 1" mesh="thigh" />
                    <geom size="0.1 0.01225 0.017" pos="0 0 -0.1" quat="0.707107 0 0.707107 0" type="box" rgba="0.913725 0.913725 0.847059 0" />
                    <body name="RL_calf" pos="0 0 -0.2">
                        <inertial pos="0.00472659 0 -0.131975" quat="0.706886 0.017653 0.017653 0.706886" mass="0.226" diaginertia="0.00340344 0.00339393 3.54834e-05" />
                        <joint name="RL_calf_joint" pos="0 0 0" axis="0 1 0" limited="true" range="-2.69653 -0.916298" />
                        <geom type="mesh" contype="0" conaffinity="0" group="1" rgba="0 0 0 1" mesh="calf" />
                        <geom size="0.1 0.008 0.008" pos="0 0 -0.1" quat="0.707107 0 0.707107 0" type="box" rgba="0 0 0 0" />
                        <geom size="0.01" pos="0 0 -0.2" contype="0" conaffinity="0" group="1" rgba="0 0 0 1" />
                        <!-- <geom size="0.02" pos="0 0 -0.2" rgba="0 0 0 1" /> -->
                        <geom type="sphere" size="0.02" pos="0 0 -0.2" priority="1" solimp="0.015 1 0.031" condim="6" friction="0.6" />
                        <site name="RL_foot" pos="0 0 -0.2" type="sphere" size=".015" />
                    </body>
                </body>
            </body>
            
        </body>
    </worldbody>

    <actuator>
        <motor joint="FR_hip_joint" name="FR_hip" gear="1" ctrllimited="true" ctrlrange="-100 100" />
        <motor joint="FR_thigh_joint" name="FR_thigh" gear="1" ctrllimited="true"
            ctrlrange="-100 100" />
        <motor joint="FR_calf_joint" name="FR_calf" gear="1" ctrllimited="true" ctrlrange="-100 100" />
        <motor joint="FL_hip_joint" name="FL_hip" gear="1" ctrllimited="true" ctrlrange="-100 100" />
        <motor joint="FL_thigh_joint" name="FL_thigh" gear="1" ctrllimited="true"
            ctrlrange="-100 100" />
        <motor joint="FL_calf_joint" name="FL_calf" gear="1" ctrllimited="true" ctrlrange="-100 100" />
        <motor joint="RR_hip_joint" name="RR_hip" gear="1" ctrllimited="true" ctrlrange="-100 100" />
        <motor joint="RR_thigh_joint" name="RR_thigh" gear="1" ctrllimited="true"
            ctrlrange="-100 100" />
        <motor joint="RR_calf_joint" name="RR_calf" gear="1" ctrllimited="true" ctrlrange="-100 100" />
        <motor joint="RL_hip_joint" name="RL_hip" gear="1" ctrllimited="true" ctrlrange="-100 100" />
        <motor joint="RL_thigh_joint" name="RL_thigh" gear="1" ctrllimited="true"
            ctrlrange="-100 100" />
        <motor joint="RL_calf_joint" name="RL_calf" gear="1" ctrllimited="true" ctrlrange="-100 100" />
    </actuator>

    <sensor>
        <framepos name="torso_pos" objtype="site" objname="imu" />
        <framequat name="Body_Quat" objtype="site" objname="imu"/>
        <framelinvel name="torso_linvel" objtype="site" objname="imu" />
        <gyro name="Body_Gyro" site="imu"/>
        <accelerometer name="Body_Acc" site="imu"/>

        <jointpos name="pos_FR_hip_joint" joint="FR_hip_joint" noise="0.001" />
        <jointpos name="pos_FR_thigh_joint" joint="FR_thigh_joint" noise="0.001" />
        <jointpos name="pos_FR_calf_joint" joint="FR_calf_joint" noise="0.001" />
        <jointpos name="pos_FL_hip_joint" joint="FL_hip_joint" noise="0.001" />
        <jointpos name="pos_FL_thigh_joint" joint="FL_thigh_joint" noise="0.001" />
        <jointpos name="pos_FL_calf_joint" joint="FL_calf_joint" noise="0.001" />
        <jointpos name="pos_RR_hip_joint" joint="RR_hip_joint" noise="0.001" />
        <jointpos name="pos_RR_thigh_joint" joint="RR_thigh_joint" noise="0.001" />
        <jointpos name="pos_RR_calf_joint" joint="RR_calf_joint" noise="0.001" />
        <jointpos name="pos_RL_hip_joint" joint="RL_hip_joint" noise="0.001" />
        <jointpos name="pos_RL_thigh_joint" joint="RL_thigh_joint" noise="0.001" />
        <jointpos name="pos_RL_calf_joint" joint="RL_calf_joint" noise="0.001" />

        <jointvel name="vel_FR_hip_joint" joint="FR_hip_joint" noise="0.1" />
        <jointvel name="vel_FR_thigh_joint" joint="FR_thigh_joint" noise="0.1" />
        <jointvel name="vel_FR_calf_joint" joint="FR_calf_joint" noise="0.1" />
        <jointvel name="vel_FL_hip_joint" joint="FL_hip_joint" noise="0.1" />
        <jointvel name="vel_FL_thigh_joint" joint="FL_thigh_joint" noise="0.1" />
        <jointvel name="vel_FL_calf_joint" joint="FL_calf_joint" noise="0.1" />
        <jointvel name="vel_RR_hip_joint" joint="RR_hip_joint" noise="0.1" />
        <jointvel name="vel_RR_thigh_joint" joint="RR_thigh_joint" noise="0.1" />
        <jointvel name="vel_RR_calf_joint" joint="RR_calf_joint" noise="0.1" />
        <jointvel name="vel_RL_hip_joint" joint="RL_hip_joint" noise="0.1" />
        <jointvel name="vel_RL_thigh_joint" joint="RL_thigh_joint" noise="0.1" />
        <jointvel name="vel_RL_calf_joint" joint="RL_calf_joint" noise="0.1" />

        <touch name="FR_touch" site="FR_foot" />
        <touch name="FL_touch" site="FL_foot" />
        <touch name="RR_touch" site="RR_foot" />
        <touch name="RL_touch" site="RL_foot" />

    </sensor>

    <keyframe>
        <key name="home"
            qpos="0 0 0.26
               1 0 0 0
               -0.000341931 0.0181576 -0.0268335
               0.00160968 0.0247957 -0.0270045
               0.00191398 -0.033048 -0.0675298
               -0.00199489 -0.0374747 -0.0681862" />
        <!-- <key name="crouch" -->
        <!--     qpos="-0.0501827 0.00107117 0.143925 -->
        <!--        1 0 0 0 -->
        <!--        0 0 -0.5 -->
        <!--        0 0 -0.5 -->
        <!--        0 0 -0.5 -->
        <!--        0 0 -0.5" /> -->
    </keyframe>

</mujoco>